2020-08-23 11:56:44,693 ERROR Error
Traceback (most recent call last):
  File "Application/testing/preparing_db.py", line 93, in add_groups
    connect_db.execute(request)
sqlite3.IntegrityError: UNIQUE constraint failed: groups.url_groups
2020-08-23 12:01:38,835 ERROR Error
Traceback (most recent call last):
  File "Application/scripts/logic/logic.py", line 90, in add_new_group
    self.connect_db.conn.execute(request)
sqlite3.IntegrityError: UNIQUE constraint failed: groups.url_groups
2020-08-23 12:01:49,741 ERROR Error
Traceback (most recent call last):
  File "Application/scripts/logic/logic.py", line 90, in add_new_group
    self.connect_db.conn.execute(request)
sqlite3.IntegrityError: UNIQUE constraint failed: groups.url_groups
2020-08-23 12:02:50,624 ERROR Error
Traceback (most recent call last):
  File "Application/scripts/logic/logic.py", line 90, in add_new_group
    self.connect_db.conn.execute(request)
sqlite3.IntegrityError: UNIQUE constraint failed: groups.url_groups
2020-08-23 12:04:21,170 ERROR Error
Traceback (most recent call last):
  File "Application/scripts/logic/logic.py", line 90, in add_new_group
    self.connect_db.conn.execute(request)
sqlite3.IntegrityError: UNIQUE constraint failed: groups.url_groups
2020-08-23 12:05:07,618 ERROR Error
Traceback (most recent call last):
  File "Application/scripts/logic/logic.py", line 90, in add_new_group
    self.connect_db.conn.execute(request)
sqlite3.IntegrityError: UNIQUE constraint failed: groups.url_groups
2020-08-23 12:05:42,343 ERROR Error
Traceback (most recent call last):
  File "Application/scripts/logic/logic.py", line 90, in add_new_group
    self.connect_db.conn.execute(request)
sqlite3.IntegrityError: UNIQUE constraint failed: groups.url_groups
2020-08-23 12:06:51,558 ERROR Error
Traceback (most recent call last):
  File "Application/scripts/logic/logic.py", line 90, in add_new_group
    self.connect_db.conn.execute(request)
sqlite3.IntegrityError: UNIQUE constraint failed: groups.url_groups
